Workbook

Sheet or2509 Parameter Sets
A1: Parameter Set | B1: Machine Cycle No | C1: Casting Part Label | D1: Datum | E1: type_1st_phase | F1: s1 | G1: v1 | H1: s2 | I1: v2 | J1: vcrit | K1: vI | L1: s3 | M1: v3 | N1: s4 | O1: s_start_braking | P1: vbrake | Q1: p0 | R1: p1 | S1: t1 | T1: p2 | U1: t2 | V1: sol_time | W1: pvac | X1: hf1 | Y1: hm2 | Z1: metal | AA1: hf2 | AB1: hf3 | AC1: f3 | AD1: f4 | AE1: hm3 | AF1: hm4 | AG1: m4 | AH1: piston | AI1: Dichteindex | AJ1: Comment | AK1: Quenching | AL1: Heat treatment | AM1: Alloy | AN1: Alloy Si | AO1: Alloy Fe | AP1: Alloy Cu | AQ1: Alloy Mn | AR1: Alloy Mg | AS1: Alloy Cr | AT1: Alloy Ni | AU1: Alloy Zn | AV1: Alloy Ti | AW1: Cavity Sensor Data File | AX1: Cavity Sensor Single Export File Path | AY1: Cavity Sensor File Cycle Nr | AZ1: Casting diagram File Path | BA1: Shot info file path | BB1: Diagnosis Diagram | BC1: Values corrected from DDM
A2: or2509-001 | B2: 12 | C2: 12 | D2: 45908 | E2: no optimization | F2: 160 | G2: 0.2 | H2: 399 | I2: 0.3 | K2: 3.3 | L2: 540 | M2: 0.5 | N2: 560 | O2: 710 | P2: 0.5 | Q2: 300 | R2: 300 | S2: 0.1 | T2: 300 | U2: 0.1 | V2: 3 | W2: 1000 | X2: 160 | Y2: 180 | Z2: 700 | AA2: 180 | AB2: 160 | AC2: 120 | AD2: 120 | AE2: 160 | AF2: 160 | AG2: 120 | AH2: 60 | AI2: 0 | AJ2: Parametric study, Baseline repeat | AK2: Air | AL2: F | AM2: 230 AlSi12(Fe) | AN2: 11.29 | AO2: 0.737 | AP2: 0.0414 | AQ2: 0.324 | AR2: 0.0273 | AS2: 0.0194 | AT2: 0.0141 | AU2: 0.0326 | AV2: 0.0233 | AW2: Data\CavitySensors\Sensordata_single_export | AX2: 250908 | AY2: 12 | AZ2: Data\ddm\ddm_y_FliesslaengerformBuehler_MachineCycleNo_pw.xml.gz | BA2: Data\dwa\dwa_y_FliesslaengerformBuehler_MachineCycleNo_pw.txt | BB2: Data\ddd\ddd_y_TIMESTAMP_FROM_DWA.xml.gz | BC2: False
A3: or2509-001 | B3: 13 | C3: 13 | D3: 45908 | E3: no optimization | F3: 160 | G3: 0.2 | H3: 399 | I3: 0.3 | K3: 3.3 | L3: 540 | M3: 0.5 | N3: 560 | O3: 710 | P3: 0.5 | Q3: 300 | R3: 300 | S3: 0.1 | T3: 300 | U3: 0.1 | V3: 3 | W3: 1000 | X3: 160 | Y3: 180 | Z3: 700 | AA3: 180 | AB3: 160 | AC3: 120 | AD3: 120 | AE3: 160 | AF3: 160 | AG3: 120 | AH3: 60 | AI3: 0 | AJ3: Parametric study, Baseline repeat | AK3: Air | AL3: F | AM3: 230 AlSi12(Fe) | AN3: 11.29 | AO3: 0.737 | AP3: 0.0414 | AQ3: 0.324 | AR3: 0.0273 | AS3: 0.0194 | AT3: 0.0141 | AU3: 0.0326 | AV3: 0.0233 | AW3: Data\CavitySensors\Sensordata_single_export | AX3: 250908 | AY3: 13 | AZ3: Data\ddm\ddm_y_FliesslaengerformBuehler_MachineCycleNo_pw.xml.gz | BA3: Data\dwa\dwa_y_FliesslaengerformBuehler_MachineCycleNo_pw.txt | BB3: Data\ddd\ddd_y_TIMESTAMP_FROM_DWA.xml.gz | BC3: False
A4: or2509-001 | B4: 14 | C4: 14 | D4: 45908 | E4: no optimization | F4: 160 | G4: 0.2 | H4: 399 | I4: 0.3 | K4: 3.3 | L4: 540 | M4: 0.5 | N4: 560 | O4: 710 | P4: 0.5 | Q4: 300 | R4: 300 | S4: 0.1 | T4: 300 | U4: 0.1 | V4: 3 | W4: 1000 | X4: 160 | Y4: 180 | Z4: 700 | AA4: 180 | AB4: 160 | AC4: 120 | AD4: 120 | AE4: 160 | AF4: 160 | AG4: 120 | AH4: 60 | AI4: 0 | AJ4: Parametric study, Baseline repeat | AK4: Air | AL4: F | AM4: 230 AlSi12(Fe) | AN4: 11.29 | AO4: 0.737 | AP4: 0.0414 | AQ4: 0.324 | AR4: 0.0273 | AS4: 0.0194 | AT4: 0.0141 | AU4: 0.0326 | AV4: 0.0233 | AW4: Data\CavitySensors\Sensordata_single_export | AX4: 250908 | AY4: 14 | AZ4: Data\ddm\ddm_y_FliesslaengerformBuehler_MachineCycleNo_pw.xml.gz | BA4: Data\dwa\dwa_y_FliesslaengerformBuehler_MachineCycleNo_pw.txt | BB4: Data\ddd\ddd_y_TIMESTAMP_FROM_DWA.xml.gz | BC4: False
A5: or2509-002 | B5: 29 | C5: 29 | D5: 45909 | E5: Buehler any | J5: 0.63 | K5: 3.5 | L5: 526 | M5: 1.7 | N5: 626 | O5: 709 | P5: 1 | Q5: 300 | R5: 500 | S5: 0.04 | T5: 600 | U5: 0.1 | V5: 16 | W5: 1000 | X5: 160 | Y5: 180 | Z5: 700 | AA5: 180 | AB5: 160 | AC5: 120 | AD5: 120 | AE5: 160 | AF5: 160 | AG5: 120 | AH5: 60 | AI5: 0.0833 | AJ5: Parametric study, preliminary tesile test | AK5: Air | AL5: F | AM5: 230 AlSi12(Fe) | AN5: 11.35 | AO5: 0.765 | AP5: 0.0357 | AQ5: 0.331 | AR5: 0.0251 | AS5: 0.0218 | AT5: 0.0132 | AU5: 0.034 | AV5: 0.0246 | AW5: Data\CavitySensors\Sensordata_single_export | AZ5: Data\ddm\ddm_y_FliesslaengerformBuehler_MachineCycleNo_pw.xml.gz | BA5: Data\dwa\dwa_y_FliesslaengerformBuehler_MachineCycleNo_pw.txt | BB5: Data\ddd\ddd_y_TIMESTAMP_FROM_DWA.xml.gz | BC5: False
A6: or2509-002 | B6: 30 | C6: 30 | D6: 45909 | E6: Buehler any | J6: 0.63 | K6: 3.5 | L6: 526 | M6: 1.7 | N6: 626 | O6: 709 | P6: 1 | Q6: 300 | R6: 500 | S6: 0.04 | T6: 600 | U6: 0.1 | V6: 16 | W6: 1000 | X6: 160 | Y6: 180 | Z6: 700 | AA6: 180 | AB6: 160 | AC6: 120 | AD6: 120 | AE6: 160 | AF6: 160 | AG6: 120 | AH6: 60 | AI6: 0.0833 | AJ6: Parametric study | AK6: Air | AL6: F | AM6: 230 AlSi12(Fe) | AN6: 11.35 | AO6: 0.765 | AP6: 0.0357 | AQ6: 0.331 | AR6: 0.0251 | AS6: 0.0218 | AT6: 0.0132 | AU6: 0.034 | AV6: 0.0246 | AW6: Data\CavitySensors\Sensordata_single_export | AX6: 250909 | AY6: 13 | AZ6: Data\ddm\ddm_y_FliesslaengerformBuehler_MachineCycleNo_pw.xml.gz | BA6: Data\dwa\dwa_y_FliesslaengerformBuehler_MachineCycleNo_pw.txt | BB6: Data\ddd\ddd_y_TIMESTAMP_FROM_DWA.xml.gz | BC6: False
A7: or2509-002 | B7: 31 | C7: 31 | D7: 45909 | E7: Buehler any | J7: 0.63 | K7: 3.5 | L7: 526 | M7: 1.7 | N7: 626 | O7: 709 | P7: 1 | Q7: 300 | R7: 500 | S7: 0.04 | T7: 600 | U7: 0.1 | V7: 16 | W7: 1000 | X7: 160 | Y7: 180 | Z7: 700 | AA7: 180 | AB7: 160 | AC7: 120 | AD7: 120 | AE7: 160 | AF7: 160 | AG7: 120 | AH7: 60 | AI7: 0.0833 | AJ7: Parametric study | AK7: Air | AL7: F | AM7: 230 AlSi12(Fe) | AN7: 11.35 | AO7: 0.765 | AP7: 0.0357 | AQ7: 0.331 | AR7: 0.0251 | AS7: 0.0218 | AT7: 0.0132 | AU7: 0.034 | AV7: 0.0246 | AW7: Data\CavitySensors\Sensordata_single_export | AX7: 250909 | AY7: 14 | AZ7: Data\ddm\ddm_y_FliesslaengerformBuehler_MachineCycleNo_pw.xml.gz | BA7: Data\dwa\dwa_y_FliesslaengerformBuehler_MachineCycleNo_pw.txt | BB7: Data\ddd\ddd_y_TIMESTAMP_FROM_DWA.xml.gz | BC7: False
A8: or2509-002 | B8: 32 | C8: 32 | D8: 45909 | E8: Buehler any | J8: 0.63 | K8: 3.5 | L8: 526 | M8: 1.7 | N8: 626 | O8: 709 | P8: 1 | Q8: 300 | R8: 500 | S8: 0.04 | T8: 600 | U8: 0.1 | V8: 16 | W8: 1000 | X8: 160 | Y8: 180 | Z8: 700 | AA8: 180 | AB8: 160 | AC8: 120 | AD8: 120 | AE8: 160 | AF8: 160 | AG8: 120 | AH8: 60 | AI8: 0.0833 | AJ8: Parametric study | AK8: Air | AL8: F | AM8: 230 AlSi12(Fe) | AN8: 11.35 | AO8: 0.765 | AP8: 0.0357 | AQ8: 0.331 | AR8: 0.0251 | AS8: 0.0218 | AT8: 0.0132 | AU8: 0.034 | AV8: 0.0246 | AW8: Data\CavitySensors\Sensordata_single_export | AX8: 250909 | AY8: 15 | AZ8: Data\ddm\ddm_y_FliesslaengerformBuehler_MachineCycleNo_pw.xml.gz | BA8: Data\dwa\dwa_y_FliesslaengerformBuehler_MachineCycleNo_pw.txt | BB8: Data\ddd\ddd_y_TIMESTAMP_FROM_DWA.xml.gz | BC8: False
A9: or2509-003 | B9: 37 | C9: 37 | D9: 45909 | E9: Buehler any | J9: 0.32 | K9: 2 | L9: 466 | M9: 1.9 | N9: 554 | O9: 699 | P9: 0.75 | Q9: 200 | R9: 500 | S9: 0.11 | T9: 500 | U9: 0.14 | V9: 16 | W9: 1000 | X9: 160 | Y9: 180 | Z9: 700 | AA9: 180 | AB9: 160 | AC9: 120 | AD9: 120 | AE9: 160 | AF9: 160 | AG9: 120 | AH9: 60 | AI9: 0.0833 | AJ9: Parametric study | AK9: Air | AL9: F | AM9: 230 AlSi12(Fe) | AN9: 11.35 | AO9: 0.765 | AP9: 0.0357 | AQ9: 0.331 | AR9: 0.0251 | AS9: 0.0218 | AT9: 0.0132 | AU9: 0.034 | AV9: 0.0246 | AW9: Data\CavitySensors\Sensordata_single_export | AX9: 250909 | AY9: 20 | AZ9: Data\ddm\ddm_y_FliesslaengerformBuehler_MachineCycleNo_pw.xml.gz | BA9: Data\dwa\dwa_y_FliesslaengerformBuehler_MachineCycleNo_pw.txt | BB9: Data\ddd\ddd_y_TIMESTAMP_FROM_DWA.xml.gz | BC9: True
A10: or2509-003 | B10: 38 | C10: lost | D10: 45909 | E10: Buehler any | J10: 0.32 | K10: 2 | L10: 466 | M10: 1.9 | N10: 554 | O10: 699 | P10: 0.75 | Q10: 200 | R10: 500 | S10: 0.11 | T10: 500 | U10: 0.14 | V10: 16 | W10: 1000 | X10: 160 | Y10: 180 | Z10: 700 | AA10: 180 | AB10: 160 | AC10: 120 | AD10: 120 | AE10: 160 | AF10: 160 | AG10: 120 | AH10: 60 | AI10: 0.0833 | AJ10: Parametric study | AK10: Air | AL10: F | AM10: 230 AlSi12(Fe) | AN10: 11.35 | AO10: 0.765 | AP10: 0.0357 | AQ10: 0.331 | AR10: 0.0251 | AS10: 0.0218 | AT10: 0.0132 | AU10: 0.034 | AV10: 0.0246 | AW10: Data\CavitySensors\Sensordata_single_export | AX10: 250909 | AY10: 21 | AZ10: Data\ddm\ddm_y_FliesslaengerformBuehler_MachineCycleNo_pw.xml.gz | BA10: Data\dwa\dwa_y_FliesslaengerformBuehler_MachineCycleNo_pw.txt | BB10: Data\ddd\ddd_y_TIMESTAMP_FROM_DWA.xml.gz | BC10: True
A11: or2509-003 | B11: 39 | C11: 39 | D11: 45909 | E11: Buehler any | J11: 0.32 | K11: 2 | L11: 466 | M11: 1.9 | N11: 554 | O11: 699 | P11: 0.75 | Q11: 200 | R11: 500 | S11: 0.11 | T11: 500 | U11: 0.14 | V11: 16 | W11: 1000 | X11: 160 | Y11: 180 | Z11: 700 | AA11: 180 | AB11: 160 | AC11: 120 | AD11: 120 | AE11: 160 | AF11: 160 | AG11: 120 | AH11: 60 | AI11: 0.0833 | AJ11: Parametric study | AK11: Air | AL11: F | AM11: 230 AlSi12(Fe) | AN11: 11.35 | AO11: 0.765 | AP11: 0.0357 | AQ11: 0.331 | AR11: 0.0251 | AS11: 0.0218 | AT11: 0.0132 | AU11: 0.034 | AV11: 0.0246 | AW11: Data\CavitySensors\Sensordata_single_export | AX11: 250909 | AY11: 22 | AZ11: Data\ddm\ddm_y_FliesslaengerformBuehler_MachineCycleNo_pw.xml.gz | BA11: Data\dwa\dwa_y_FliesslaengerformBuehler_MachineCycleNo_pw.txt | BB11: Data\ddd\ddd_y_TIMESTAMP_FROM_DWA.xml.gz | BC11: True
A12: or2509-004 | B12: 48 | C12: 48 | D12: 45909 | E12: Nogowizin | K12: 4 | L12: 566 | M12: 1.8 | N12: 646 | O12: 679 | P12: 0.75 | Q12: 200 | R12: 400 | S12: 0.07 | T12: 600 | U12: 0.09 | V12: 8 | W12: 1000 | X12: 160 | Y12: 150 | Z12: 700 | AA12: 180 | AB12: 160 | AC12: 120 | AD12: 120 | AE12: 130 | AF12: 130 | AG12: 90 | AH12: 60 | AI12: 0.0833 | AJ12: Parametric study | AK12: Air | AL12: F | AM12: 230 AlSi12(Fe) | AN12: 11.35 | AO12: 0.765 | AP12: 0.0357 | AQ12: 0.331 | AR12: 0.0251 | AS12: 0.0218 | AT12: 0.0132 | AU12: 0.034 | AV12: 0.0246 | AW12: Data\CavitySensors\Sensordata_single_export | AX12: 250909 | AY12: 31 | AZ12: Data\ddm\ddm_y_FliesslaengerformBuehler_MachineCycleNo_pw.xml.gz | BA12: Data\dwa\dwa_y_FliesslaengerformBuehler_MachineCycleNo_pw.txt | BB12: Data\ddd\ddd_y_TIMESTAMP_FROM_DWA.xml.gz | BC12: False
A13: or2509-004 | B13: 49 | C13: 49 | D13: 45909 | E13: Nogowizin | K13: 4 | L13: 566 | M13: 1.8 | N13: 646 | O13: 679 | P13: 0.75 | Q13: 200 | R13: 400 | S13: 0.07 | T13: 600 | U13: 0.09 | V13: 8 | W13: 1000 | X13: 160 | Y13: 150 | Z13: 700 | AA13: 180 | AB13: 160 | AC13: 120 | AD13: 120 | AE13: 130 | AF13: 130 | AG13: 90 | AH13: 60 | AI13: 0.0833 | AJ13: Parametric study | AK13: Air | AL13: F | AM13: 230 AlSi12(Fe) | AN13: 11.35 | AO13: 0.765 | AP13: 0.0357 | AQ13: 0.331 | AR13: 0.0251 | AS13: 0.0218 | AT13: 0.0132 | AU13: 0.034 | AV13: 0.0246 | AW13: Data\CavitySensors\Sensordata_single_export | AX13: 250909 | AY13: 32 | AZ13: Data\ddm\ddm_y_FliesslaengerformBuehler_MachineCycleNo_pw.xml.gz | BA13: Data\dwa\dwa_y_FliesslaengerformBuehler_MachineCycleNo_pw.txt | BB13: Data\ddd\ddd_y_TIMESTAMP_FROM_DWA.xml.gz | BC13: False
A14: or2509-004 | B14: 50 | C14: 50 | D14: 45909 | E14: Nogowizin | K14: 4 | L14: 566 | M14: 1.8 | N14: 646 | O14: 679 | P14: 0.75 | Q14: 200 | R14: 400 | S14: 0.07 | T14: 600 | U14: 0.09 | V14: 8 | W14: 1000 | X14: 160 | Y14: 150 | Z14: 700 | AA14: 180 | AB14: 160 | AC14: 120 | AD14: 120 | AE14: 130 | AF14: 130 | AG14: 90 | AH14: 60 | AI14: 0.0833 | AJ14: Parametric study | AK14: Air | AL14: F | AM14: 230 AlSi12(Fe) | AN14: 11.35 | AO14: 0.765 | AP14: 0.0357 | AQ14: 0.331 | AR14: 0.0251 | AS14: 0.0218 | AT14: 0.0132 | AU14: 0.034 | AV14: 0.0246 | AW14: Data\CavitySensors\Sensordata_single_export | AX14: 250909 | AY14: 33 | AZ14: Data\ddm\ddm_y_FliesslaengerformBuehler_MachineCycleNo_pw.xml.gz | BA14: Data\dwa\dwa_y_FliesslaengerformBuehler_MachineCycleNo_pw.txt | BB14: Data\ddd\ddd_y_TIMESTAMP_FROM_DWA.xml.gz | BC14: False
A15: or2509-005 | B15: 57 | C15: 57 | D15: 45909 | E15: Buehler any | J15: 0.63 | K15: 4 | L15: 566 | M15: 1.8 | N15: 646 | O15: 679 | P15: 0.75 | Q15: 200 | R15: 400 | S15: 0.07 | T15: 600 | U15: 0.09 | V15: 4 | W15: 500 | X15: 160 | Y15: 150 | Z15: 700 | AA15: 180 | AB15: 160 | AC15: 120 | AD15: 120 | AE15: 130 | AF15: 130 | AG15: 90 | AH15: 60 | AI15: 0.0833 | AJ15: Parametric study | AK15: Air | AL15: F | AM15: 230 AlSi12(Fe) | AN15: 11.35 | AO15: 0.765 | AP15: 0.0357 | AQ15: 0.331 | AR15: 0.0251 | AS15: 0.0218 | AT15: 0.0132 | AU15: 0.034 | AV15: 0.0246 | AW15: Data\CavitySensors\Sensordata_single_export | AX15: 250909 | AY15: 40 | AZ15: Data\ddm\ddm_y_FliesslaengerformBuehler_MachineCycleNo_pw.xml.gz | BA15: Data\dwa\dwa_y_FliesslaengerformBuehler_MachineCycleNo_pw.txt | BB15: Data\ddd\ddd_y_TIMESTAMP_FROM_DWA.xml.gz | BC15: True
A16: or2509-005 | B16: 58 | C16: 58 | D16: 45909 | E16: Buehler any | J16: 0.63 | K16: 4 | L16: 566 | M16: 1.8 | N16: 646 | O16: 679 | P16: 0.75 | Q16: 200 | R16: 400 | S16: 0.07 | T16: 600 | U16: 0.09 | V16: 4 | W16: 500 | X16: 160 | Y16: 150 | Z16: 700 | AA16: 180 | AB16: 160 | AC16: 120 | AD16: 120 | AE16: 130 | AF16: 130 | AG16: 90 | AH16: 60 | AI16: 0.0833 | AJ16: Parametric study | AK16: Air | AL16: F | AM16: 230 AlSi12(Fe) | AN16: 11.35 | AO16: 0.765 | AP16: 0.0357 | AQ16: 0.331 | AR16: 0.0251 | AS16: 0.0218 | AT16: 0.0132 | AU16: 0.034 | AV16: 0.0246 | AW16: Data\CavitySensors\Sensordata_single_export | AX16: 250909 | AY16: 41 | AZ16: Data\ddm\ddm_y_FliesslaengerformBuehler_MachineCycleNo_pw.xml.gz | BA16: Data\dwa\dwa_y_FliesslaengerformBuehler_MachineCycleNo_pw.txt | BB16: Data\ddd\ddd_y_TIMESTAMP_FROM_DWA.xml.gz | BC16: True
A17: or2509-005 | B17: 59 | C17: 59 | D17: 45909 | E17: Buehler any | J17: 0.63 | K17: 4 | L17: 566 | M17: 1.8 | N17: 646 | O17: 679 | P17: 0.75 | Q17: 200 | R17: 400 | S17: 0.07 | T17: 600 | U17: 0.09 | V17: 4 | W17: 500 | X17: 160 | Y17: 150 | Z17: 700 | AA17: 180 | AB17: 160 | AC17: 120 | AD17: 120 | AE17: 130 | AF17: 130 | AG17: 90 | AH17: 60 | AI17: 0.0833 | AJ17: Parametric study | AK17: Air | AL17: F | AM17: 230 AlSi12(Fe) | AN17: 11.35 | AO17: 0.765 | AP17: 0.0357 | AQ17: 0.331 | AR17: 0.0251 | AS17: 0.0218 | AT17: 0.0132 | AU17: 0.034 | AV17: 0.0246 | AW17: Data\CavitySensors\Sensordata_single_export | AX17: 250909 | AY17: 42 | AZ17: Data\ddm\ddm_y_FliesslaengerformBuehler_MachineCycleNo_pw.xml.gz | BA17: Data\dwa\dwa_y_FliesslaengerformBuehler_MachineCycleNo_pw.txt | BB17: Data\ddd\ddd_y_TIMESTAMP_FROM_DWA.xml.gz | BC17: True
A18: or2509-006 | B18: 63 | C18: 63 | D18: 45909 | E18: Nogowizin | K18: 2.5 | L18: 466 | M18: 1.8 | N18: 546 | O18: 699 | P18: 1 | Q18: 200 | R18: 400 | S18: 0.06 | T18: 700 | U18: 0.14 | V18: 16 | W18: 1000 | X18: 160 | Y18: 150 | Z18: 700 | AA18: 180 | AB18: 160 | AC18: 120 | AD18: 120 | AE18: 130 | AF18: 130 | AG18: 90 | AH18: 60 | AI18: 0.0833 | AJ18: Parametric study | AK18: Air | AL18: F | AM18: 230 AlSi12(Fe) | AN18: 11.35 | AO18: 0.765 | AP18: 0.0357 | AQ18: 0.331 | AR18: 0.0251 | AS18: 0.0218 | AT18: 0.0132 | AU18: 0.034 | AV18: 0.0246 | AW18: Data\CavitySensors\Sensordata_single_export | AX18: 250909 | AY18: 46 | AZ18: Data\ddm\ddm_y_FliesslaengerformBuehler_MachineCycleNo_pw.xml.gz | BA18: Data\dwa\dwa_y_FliesslaengerformBuehler_MachineCycleNo_pw.txt | BB18: Data\ddd\ddd_y_TIMESTAMP_FROM_DWA.xml.gz | BC18: False
A19: or2509-006 | B19: 64 | C19: 64 | D19: 45909 | E19: Nogowizin | K19: 2.5 | L19: 466 | M19: 1.8 | N19: 546 | O19: 699 | P19: 1 | Q19: 200 | R19: 400 | S19: 0.06 | T19: 700 | U19: 0.14 | V19: 16 | W19: 1000 | X19: 160 | Y19: 150 | Z19: 700 | AA19: 180 | AB19: 160 | AC19: 120 | AD19: 120 | AE19: 130 | AF19: 130 | AG19: 90 | AH19: 60 | AI19: 0.0833 | AJ19: Parametric study | AK19: Air | AL19: F | AM19: 230 AlSi12(Fe) | AN19: 11.35 | AO19: 0.765 | AP19: 0.0357 | AQ19: 0.331 | AR19: 0.0251 | AS19: 0.0218 | AT19: 0.0132 | AU19: 0.034 | AV19: 0.0246 | AW19: Data\CavitySensors\Sensordata_single_export | AX19: 250909 | AY19: 47 | AZ19: Data\ddm\ddm_y_FliesslaengerformBuehler_MachineCycleNo_pw.xml.gz | BA19: Data\dwa\dwa_y_FliesslaengerformBuehler_MachineCycleNo_pw.txt | BB19: Data\ddd\ddd_y_TIMESTAMP_FROM_DWA.xml.gz | BC19: False
A20: or2509-006 | B20: 65 | C20: 65 | D20: 45909 | E20: Nogowizin | K20: 2.5 | L20: 466 | M20: 1.8 | N20: 546 | O20: 699 | P20: 1 | Q20: 200 | R20: 400 | S20: 0.06 | T20: 700 | U20: 0.14 | V20: 16 | W20: 1000 | X20: 160 | Y20: 150 | Z20: 700 | AA20: 180 | AB20: 160 | AC20: 120 | AD20: 120 | AE20: 130 | AF20: 130 | AG20: 90 | AH20: 60 | AI20: 0.0833 | AJ20: Parametric study | AK20: Air | AL20: F | AM20: 230 AlSi12(Fe) | AN20: 11.35 | AO20: 0.765 | AP20: 0.0357 | AQ20: 0.331 | AR20: 0.0251 | AS20: 0.0218 | AT20: 0.0132 | AU20: 0.034 | AV20: 0.0246 | AW20: Data\CavitySensors\Sensordata_single_export | AX20: 250909 | AY20: 48 | AZ20: Data\ddm\ddm_y_FliesslaengerformBuehler_MachineCycleNo_pw.xml.gz | BA20: Data\dwa\dwa_y_FliesslaengerformBuehler_MachineCycleNo_pw.txt | BB20: Data\ddd\ddd_y_TIMESTAMP_FROM_DWA.xml.gz | BC20: False
A21: or2509-007 | B21: 69 | C21: 69 | D21: 45909 | E21: Nogowizin | K21: 3.5 | L21: 566 | M21: 3.2 | N21: 666 | O21: 689 | P21: 0.75 | Q21: 200 | R21: 200 | S21: 0.07 | T21: 400 | U21: 0.11 | V21: 4 | W21: 500 | X21: 160 | Y21: 150 | Z21: 700 | AA21: 180 | AB21: 160 | AC21: 120 | AD21: 120 | AE21: 130 | AF21: 130 | AG21: 90 | AH21: 60 | AI21: 0.0833 | AJ21: Parametric study | AK21: Air | AL21: F | AM21: 230 AlSi12(Fe) | AN21: 11.35 | AO21: 0.765 | AP21: 0.0357 | AQ21: 0.331 | AR21: 0.0251 | AS21: 0.0218 | AT21: 0.0132 | AU21: 0.034 | AV21: 0.0246 | AW21: Data\CavitySensors\Sensordata_single_export | AX21: 250909 | AY21: 52 | AZ21: Data\ddm\ddm_y_FliesslaengerformBuehler_MachineCycleNo_pw.xml.gz | BA21: Data\dwa\dwa_y_FliesslaengerformBuehler_MachineCycleNo_pw.txt | BB21: Data\ddd\ddd_y_TIMESTAMP_FROM_DWA.xml.gz | BC21: False
A22: or2509-007 | B22: 70 | C22: 70 | D22: 45909 | E22: Nogowizin | K22: 3.5 | L22: 566 | M22: 3.2 | N22: 666 | O22: 689 | P22: 0.75 | Q22: 200 | R22: 200 | S22: 0.07 | T22: 400 | U22: 0.11 | V22: 4 | W22: 500 | X22: 160 | Y22: 150 | Z22: 700 | AA22: 180 | AB22: 160 | AC22: 120 | AD22: 120 | AE22: 130 | AF22: 130 | AG22: 90 | AH22: 60 | AI22: 0.0833 | AJ22: Parametric study | AK22: Air | AL22: F | AM22: 230 AlSi12(Fe) | AN22: 11.35 | AO22: 0.765 | AP22: 0.0357 | AQ22: 0.331 | AR22: 0.0251 | AS22: 0.0218 | AT22: 0.0132 | AU22: 0.034 | AV22: 0.0246 | AW22: Data\CavitySensors\Sensordata_single_export | AX22: 250909 | AY22: 53 | AZ22: Data\ddm\ddm_y_FliesslaengerformBuehler_MachineCycleNo_pw.xml.gz | BA22: Data\dwa\dwa_y_FliesslaengerformBuehler_MachineCycleNo_pw.txt | BB22: Data\ddd\ddd_y_TIMESTAMP_FROM_DWA.xml.gz | BC22: False
A23: or2509-007 | B23: 71 | C23: 71 | D23: 45909 | E23: Nogowizin | K23: 3.5 | L23: 566 | M23: 3.2 | N23: 666 | O23: 689 | P23: 0.75 | Q23: 200 | R23: 200 | S23: 0.07 | T23: 400 | U23: 0.11 | V23: 4 | W23: 500 | X23: 160 | Y23: 150 | Z23: 700 | AA23: 180 | AB23: 160 | AC23: 120 | AD23: 120 | AE23: 130 | AF23: 130 | AG23: 90 | AH23: 60 | AI23: 0.0833 | AJ23: Parametric study | AK23: Air | AL23: F | AM23: 230 AlSi12(Fe) | AN23: 11.35 | AO23: 0.765 | AP23: 0.0357 | AQ23: 0.331 | AR23: 0.0251 | AS23: 0.0218 | AT23: 0.0132 | AU23: 0.034 | AV23: 0.0246 | AW23: Data\CavitySensors\Sensordata_single_export | AX23: 250909 | AY23: 54 | AZ23: Data\ddm\ddm_y_FliesslaengerformBuehler_MachineCycleNo_pw.xml.gz | BA23: Data\dwa\dwa_y_FliesslaengerformBuehler_MachineCycleNo_pw.txt | BB23: Data\ddd\ddd_y_TIMESTAMP_FROM_DWA.xml.gz | BC23: False
A24: or2509-008 | B24: 78 | C24: 78 | D24: 45909 | E24: Nogowizin | K24: 3.2 | L24: 486 | M24: 1.9 | N24: 566 | O24: 689 | P24: 1 | Q24: 200 | R24: 200 | S24: 0.08 | T24: 400 | U24: 0.18 | V24: 8 | W24: 1000 | X24: 160 | Y24: 150 | Z24: 700 | AA24: 180 | AB24: 160 | AC24: 120 | AD24: 120 | AE24: 130 | AF24: 130 | AG24: 90 | AH24: 60 | AI24: 0.0833 | AJ24: Parametric study, preliminary tesile test | AK24: Air | AL24: F | AM24: 230 AlSi12(Fe) | AN24: 11.35 | AO24: 0.765 | AP24: 0.0357 | AQ24: 0.331 | AR24: 0.0251 | AS24: 0.0218 | AT24: 0.0132 | AU24: 0.034 | AV24: 0.0246 | AW24: Data\CavitySensors\Sensordata_single_export | AZ24: Data\ddm\ddm_y_FliesslaengerformBuehler_MachineCycleNo_pw.xml.gz | BA24: Data\dwa\dwa_y_FliesslaengerformBuehler_MachineCycleNo_pw.txt | BB24: Data\ddd\ddd_y_TIMESTAMP_FROM_DWA.xml.gz | BC24: True
A25: or2509-008 | B25: 79 | C25: 79 | D25: 45909 | E25: Nogowizin | K25: 3.2 | L25: 486 | M25: 1.9 | N25: 566 | O25: 689 | P25: 1 | Q25: 200 | R25: 200 | S25: 0.08 | T25: 400 | U25: 0.18 | V25: 8 | W25: 1000 | X25: 160 | Y25: 150 | Z25: 700 | AA25: 180 | AB25: 160 | AC25: 120 | AD25: 120 | AE25: 130 | AF25: 130 | AG25: 90 | AH25: 60 | AI25: 0.0833 | AJ25: Parametric study | AK25: Air | AL25: F | AM25: 230 AlSi12(Fe) | AN25: 11.35 | AO25: 0.765 | AP25: 0.0357 | AQ25: 0.331 | AR25: 0.0251 | AS25: 0.0218 | AT25: 0.0132 | AU25: 0.034 | AV25: 0.0246 | AW25: Data\CavitySensors\Sensordata_single_export | AX25: 250909 | AY25: 62 | AZ25: Data\ddm\ddm_y_FliesslaengerformBuehler_MachineCycleNo_pw.xml.gz | BA25: Data\dwa\dwa_y_FliesslaengerformBuehler_MachineCycleNo_pw.txt | BB25: Data\ddd\ddd_y_TIMESTAMP_FROM_DWA.xml.gz | BC25: True
A26: or2509-008 | B26: 80 | C26: 80 | D26: 45909 | E26: Nogowizin | K26: 3.2 | L26: 486 | M26: 1.9 | N26: 566 | O26: 689 | P26: 1 | Q26: 200 | R26: 200 | S26: 0.08 | T26: 400 | U26: 0.18 | V26: 8 | W26: 1000 | X26: 160 | Y26: 150 | Z26: 700 | AA26: 180 | AB26: 160 | AC26: 120 | AD26: 120 | AE26: 130 | AF26: 130 | AG26: 90 | AH26: 60 | AI26: 0.0833 | AJ26: Parametric study | AK26: Air | AL26: F | AM26: 230 AlSi12(Fe) | AN26: 11.35 | AO26: 0.765 | AP26: 0.0357 | AQ26: 0.331 | AR26: 0.0251 | AS26: 0.0218 | AT26: 0.0132 | AU26: 0.034 | AV26: 0.0246 | AW26: Data\CavitySensors\Sensordata_single_export | AX26: 250909 | AY26: 63 | AZ26: Data\ddm\ddm_y_FliesslaengerformBuehler_MachineCycleNo_pw.xml.gz | BA26: Data\dwa\dwa_y_FliesslaengerformBuehler_MachineCycleNo_pw.txt | BB26: Data\ddd\ddd_y_TIMESTAMP_FROM_DWA.xml.gz | BC26: True
A27: or2509-008 | B27: 81 | C27: 81 | D27: 45909 | E27: Nogowizin | K27: 3.2 | L27: 486 | M27: 1.9 | N27: 566 | O27: 689 | P27: 1 | Q27: 200 | R27: 200 | S27: 0.08 | T27: 400 | U27: 0.18 | V27: 8 | W27: 1000 | X27: 160 | Y27: 150 | Z27: 700 | AA27: 180 | AB27: 160 | AC27: 120 | AD27: 120 | AE27: 130 | AF27: 130 | AG27: 90 | AH27: 60 | AI27: 0.0833 | AJ27: Parametric study | AK27: Air | AL27: F | AM27: 230 AlSi12(Fe) | AN27: 11.35 | AO27: 0.765 | AP27: 0.0357 | AQ27: 0.331 | AR27: 0.0251 | AS27: 0.0218 | AT27: 0.0132 | AU27: 0.034 | AV27: 0.0246 | AW27: Data\CavitySensors\Sensordata_single_export | AX27: 250909 | AY27: 64 | AZ27: Data\ddm\ddm_y_FliesslaengerformBuehler_MachineCycleNo_pw.xml.gz | BA27: Data\dwa\dwa_y_FliesslaengerformBuehler_MachineCycleNo_pw.txt | BB27: Data\ddd\ddd_y_TIMESTAMP_FROM_DWA.xml.gz | BC27: True
A28: or2509-009 | B28: 85 | C28: 85 | D28: 45909 | E28: Buehler any | J28: 0.57 | K28: 3.5 | L28: 586 | M28: 1.1 | N28: 666 | O28: 689 | P28: 0.75 | Q28: 200 | R28: 500 | S28: 0.07 | T28: 500 | U28: 0.17 | V28: 16 | W28: 1000 | X28: 160 | Y28: 150 | Z28: 700 | AA28: 180 | AB28: 160 | AC28: 120 | AD28: 120 | AE28: 130 | AF28: 130 | AG28: 90 | AH28: 60 | AI28: 0.0833 | AJ28: Parametric study | AK28: Air | AL28: F | AM28: 230 AlSi12(Fe) | AN28: 11.35 | AO28: 0.765 | AP28: 0.0357 | AQ28: 0.331 | AR28: 0.0251 | AS28: 0.0218 | AT28: 0.0132 | AU28: 0.034 | AV28: 0.0246 | AW28: Data\CavitySensors\Sensordata_single_export | AX28: 250909 | AY28: 68 | AZ28: Data\ddm\ddm_y_FliesslaengerformBuehler_MachineCycleNo_pw.xml.gz | BA28: Data\dwa\dwa_y_FliesslaengerformBuehler_MachineCycleNo_pw.txt | BB28: Data\ddd\ddd_y_TIMESTAMP_FROM_DWA.xml.gz | BC28: False
A29: or2509-009 | B29: 86 | C29: 86 | D29: 45909 | E29: Buehler any | J29: 0.57 | K29: 3.5 | L29: 586 | M29: 1.1 | N29: 666 | O29: 689 | P29: 0.75 | Q29: 200 | R29: 500 | S29: 0.07 | T29: 500 | U29: 0.17 | V29: 16 | W29: 1000 | X29: 160 | Y29: 150 | Z29: 700 | AA29: 180 | AB29: 160 | AC29: 120 | AD29: 120 | AE29: 130 | AF29: 130 | AG29: 90 | AH29: 60 | AI29: 0.0833 | AJ29: Parametric study | AK29: Air | AL29: F | AM29: 230 AlSi12(Fe) | AN29: 11.35 | AO29: 0.765 | AP29: 0.0357 | AQ29: 0.331 | AR29: 0.0251 | AS29: 0.0218 | AT29: 0.0132 | AU29: 0.034 | AV29: 0.0246 | AW29: Data\CavitySensors\Sensordata_single_export | AX29: 250909 | AY29: 69 | AZ29: Data\ddm\ddm_y_FliesslaengerformBuehler_MachineCycleNo_pw.xml.gz | BA29: Data\dwa\dwa_y_FliesslaengerformBuehler_MachineCycleNo_pw.txt | BB29: Data\ddd\ddd_y_TIMESTAMP_FROM_DWA.xml.gz | BC29: False
A30: or2509-009 | B30: 87 | C30: 87 | D30: 45909 | E30: Buehler any | J30: 0.57 | K30: 3.5 | L30: 586 | M30: 1.1 | N30: 666 | O30: 689 | P30: 0.75 | Q30: 200 | R30: 500 | S30: 0.07 | T30: 500 | U30: 0.17 | V30: 16 | W30: 1000 | X30: 160 | Y30: 150 | Z30: 700 | AA30: 180 | AB30: 160 | AC30: 120 | AD30: 120 | AE30: 130 | AF30: 130 | AG30: 90 | AH30: 60 | AI30: 0.0833 | AJ30: Parametric study | AK30: Air | AL30: F | AM30: 230 AlSi12(Fe) | AN30: 11.35 | AO30: 0.765 | AP30: 0.0357 | AQ30: 0.331 | AR30: 0.0251 | AS30: 0.0218 | AT30: 0.0132 | AU30: 0.034 | AV30: 0.0246 | AW30: Data\CavitySensors\Sensordata_single_export | AX30: 250909 | AY30: 70 | AZ30: Data\ddm\ddm_y_FliesslaengerformBuehler_MachineCycleNo_pw.xml.gz | BA30: Data\dwa\dwa_y_FliesslaengerformBuehler_MachineCycleNo_pw.txt | BB30: Data\ddd\ddd_y_TIMESTAMP_FROM_DWA.xml.gz | BC30: False
A31: or2509-010 | B31: 91 | C31: 91 | D31: 45909 | E31: Buehler any | J31: 0.38 | K31: 3 | L31: 486 | M31: 2.6 | N31: 566 | O31: 699 | P31: 0.75 | Q31: 200 | R31: 300 | S31: 0.05 | T31: 400 | U31: 0.15 | V31: 16 | W31: 500 | X31: 160 | Y31: 150 | Z31: 700 | AA31: 180 | AB31: 160 | AC31: 120 | AD31: 120 | AE31: 130 | AF31: 130 | AG31: 90 | AH31: 60 | AI31: 0.0833 | AJ31: Parametric study | AK31: Air | AL31: F | AM31: 230 AlSi12(Fe) | AN31: 11.35 | AO31: 0.765 | AP31: 0.0357 | AQ31: 0.331 | AR31: 0.0251 | AS31: 0.0218 | AT31: 0.0132 | AU31: 0.034 | AV31: 0.0246 | AW31: Data\CavitySensors\Sensordata_single_export | AX31: 250909 | AY31: 74 | AZ31: Data\ddm\ddm_y_FliesslaengerformBuehler_MachineCycleNo_pw.xml.gz | BA31: Data\dwa\dwa_y_FliesslaengerformBuehler_MachineCycleNo_pw.txt | BB31: Data\ddd\ddd_y_TIMESTAMP_FROM_DWA.xml.gz | BC31: False
A32: or2509-010 | B32: 92 | C32: 92 | D32: 45909 | E32: Buehler any | J32: 0.38 | K32: 3 | L32: 486 | M32: 2.6 | N32: 566 | O32: 699 | P32: 0.75 | Q32: 200 | R32: 300 | S32: 0.05 | T32: 400 | U32: 0.15 | V32: 16 | W32: 500 | X32: 160 | Y32: 150 | Z32: 700 | AA32: 180 | AB32: 160 | AC32: 120 | AD32: 120 | AE32: 130 | AF32: 130 | AG32: 90 | AH32: 60 | AI32: 0.0833 | AJ32: Parametric study | AK32: Air | AL32: F | AM32: 230 AlSi12(Fe) | AN32: 11.35 | AO32: 0.765 | AP32: 0.0357 | AQ32: 0.331 | AR32: 0.0251 | AS32: 0.0218 | AT32: 0.0132 | AU32: 0.034 | AV32: 0.0246 | AW32: Data\CavitySensors\Sensordata_single_export | AX32: 250909 | AY32: 75 | AZ32: Data\ddm\ddm_y_FliesslaengerformBuehler_MachineCycleNo_pw.xml.gz | BA32: Data\dwa\dwa_y_FliesslaengerformBuehler_MachineCycleNo_pw.txt | BB32: Data\ddd\ddd_y_TIMESTAMP_FROM_DWA.xml.gz | BC32: False
A33: or2509-010 | B33: 93 | C33: 93 | D33: 45909 | E33: Buehler any | J33: 0.38 | K33: 3 | L33: 486 | M33: 2.6 | N33: 566 | O33: 699 | P33: 0.75 | Q33: 200 | R33: 300 | S33: 0.05 | T33: 400 | U33: 0.15 | V33: 16 | W33: 500 | X33: 160 | Y33: 150 | Z33: 700 | AA33: 180 | AB33: 160 | AC33: 120 | AD33: 120 | AE33: 130 | AF33: 130 | AG33: 90 | AH33: 60 | AI33: 0.0833 | AJ33: Parametric study | AK33: Air | AL33: F | AM33: 230 AlSi12(Fe) | AN33: 11.35 | AO33: 0.765 | AP33: 0.0357 | AQ33: 0.331 | AR33: 0.0251 | AS33: 0.0218 | AT33: 0.0132 | AU33: 0.034 | AV33: 0.0246 | AW33: Data\CavitySensors\Sensordata_single_export | AX33: 250909 | AY33: 76 | AZ33: Data\ddm\ddm_y_FliesslaengerformBuehler_MachineCycleNo_pw.xml.gz | BA33: Data\dwa\dwa_y_FliesslaengerformBuehler_MachineCycleNo_pw.txt | BB33: Data\ddd\ddd_y_TIMESTAMP_FROM_DWA.xml.gz | BC33: False
A34: or2509-011 | B34: 104 | C34: 104 | D34: 45910 | E34: Nogowizin | K34: 2 | L34: 526.1831 | M34: 1.8 | N34: 586.1831 | O34: 699 | P34: 0.75 | Q34: 300 | R34: 300 | S34: 0.06 | T34: 300 | U34: 0.1 | V34: 16 | W34: 1000 | X34: 130 | Y34: 180 | Z34: 680 | AA34: 150 | AB34: 130 | AC34: 90 | AD34: 90 | AE34: 160 | AF34: 160 | AG34: 120 | AH34: 60 | AI34: 0.0453 | AJ34: Parametric study | AK34: Air | AL34: F | AM34: 230 AlSi12(Fe) | AN34: 11.31 | AO34: 0.762 | AP34: 0.0351 | AQ34: 0.33 | AR34: 0.024 | AS34: 0.022 | AT34: 0.0131 | AU34: 0.0337 | AV34: 0.0248 | AW34: Data\CavitySensors\Sensordata_single_export | AX34: 250910 | AY34: 9 | AZ34: Data\ddm\ddm_y_FliesslaengerformBuehler_MachineCycleNo_pw.xml.gz | BA34: Data\dwa\dwa_y_FliesslaengerformBuehler_MachineCycleNo_pw.txt | BB34: Data\ddd\ddd_y_TIMESTAMP_FROM_DWA.xml.gz | BC34: False
A35: or2509-011 | B35: 105 | C35: 105 | D35: 45910 | E35: Nogowizin | K35: 2 | L35: 526.1831 | M35: 1.8 | N35: 586.1831 | O35: 699 | P35: 0.75 | Q35: 300 | R35: 300 | S35: 0.06 | T35: 300 | U35: 0.1 | V35: 16 | W35: 1000 | X35: 130 | Y35: 180 | Z35: 680 | AA35: 150 | AB35: 130 | AC35: 90 | AD35: 90 | AE35: 160 | AF35: 160 | AG35: 120 | AH35: 60 | AI35: 0.0453 | AJ35: Parametric study | AK35: Air | AL35: F | AM35: 230 AlSi12(Fe) | AN35: 11.31 | AO35: 0.762 | AP35: 0.0351 | AQ35: 0.33 | AR35: 0.024 | AS35: 0.022 | AT35: 0.0131 | AU35: 0.0337 | AV35: 0.0248 | AW35: Data\CavitySensors\Sensordata_single_export | AX35: 250910 | AY35: 10 | AZ35: Data\ddm\ddm_y_FliesslaengerformBuehler_MachineCycleNo_pw.xml.gz | BA35: Data\dwa\dwa_y_FliesslaengerformBuehler_MachineCycleNo_pw.txt | BB35: Data\ddd\ddd_y_TIMESTAMP_FROM_DWA.xml.gz | BC35: False
A36: or2509-011 | B36: 106 | C36: 106 | D36: 45910 | E36: Nogowizin | K36: 2 | L36: 526.1831 | M36: 1.8 | N36: 586.1831 | O36: 699 | P36: 0.75 | Q36: 300 | R36: 300 | S36: 0.06 | T36: 300 | U36: 0.1 | V36: 16 | W36: 1000 | X36: 130 | Y36: 180 | Z36: 680 | AA36: 150 | AB36: 130 | AC36: 90 | AD36: 90 | AE36: 160 | AF36: 160 | AG36: 120 | AH36: 60 | AI36: 0.0453 | AJ36: Parametric study | AK36: Air | AL36: F | AM36: 230 AlSi12(Fe) | AN36: 11.31 | AO36: 0.762 | AP36: 0.0351 | AQ36: 0.33 | AR36: 0.024 | AS36: 0.022 | AT36: 0.0131 | AU36: 0.0337 | AV36: 0.0248 | AW36: Data\CavitySensors\Sensordata_single_export | AX36: 250910 | AY36: 11 | AZ36: Data\ddm\ddm_y_FliesslaengerformBuehler_MachineCycleNo_pw.xml.gz | BA36: Data\dwa\dwa_y_FliesslaengerformBuehler_MachineCycleNo_pw.txt | BB36: Data\ddd\ddd_y_TIMESTAMP_FROM_DWA.xml.gz | BC36: False
A37: or2509-012 | B37: 112 | C37: 112 | D37: 45910 | E37: no optimization | F37: 280 | G37: 0.1 | H37: 420 | I37: 0.1 | K37: 2.5 | L37: 566.1831 | M37: 0.3 | N37: 666.1831 | O37: 679 | P37: 1.25 | Q37: 400 | R37: 400 | S37: 0.07 | T37: 400 | U37: 0.09 | V37: 16 | W37: 10 | X37: 130 | Y37: 180 | Z37: 680 | AA37: 150 | AB37: 130 | AC37: 90 | AD37: 90 | AE37: 160 | AF37: 160 | AG37: 120 | AH37: 60 | AI37: 0.0453 | AJ37: Parametric study | AK37: Air | AL37: F | AM37: 230 AlSi12(Fe) | AN37: 11.31 | AO37: 0.762 | AP37: 0.0351 | AQ37: 0.33 | AR37: 0.024 | AS37: 0.022 | AT37: 0.0131 | AU37: 0.0337 | AV37: 0.0248 | AW37: Data\CavitySensors\Sensordata_single_export | AX37: 250910 | AY37: 17 | AZ37: Data\ddm\ddm_y_FliesslaengerformBuehler_MachineCycleNo_pw.xml.gz | BA37: Data\dwa\dwa_y_FliesslaengerformBuehler_MachineCycleNo_pw.txt | BB37: Data\ddd\ddd_y_TIMESTAMP_FROM_DWA.xml.gz | BC37: False
A38: or2509-012 | B38: 113 | C38: 113 | D38: 45910 | E38: no optimization | F38: 280 | G38: 0.1 | H38: 420 | I38: 0.1 | K38: 2.5 | L38: 566.1831 | M38: 0.3 | N38: 666.1831 | O38: 679 | P38: 1.25 | Q38: 400 | R38: 400 | S38: 0.07 | T38: 400 | U38: 0.09 | V38: 16 | W38: 10 | X38: 130 | Y38: 180 | Z38: 680 | AA38: 150 | AB38: 130 | AC38: 90 | AD38: 90 | AE38: 160 | AF38: 160 | AG38: 120 | AH38: 60 | AI38: 0.0453 | AJ38: Parametric study | AK38: Air | AL38: F | AM38: 230 AlSi12(Fe) | AN38: 11.31 | AO38: 0.762 | AP38: 0.0351 | AQ38: 0.33 | AR38: 0.024 | AS38: 0.022 | AT38: 0.0131 | AU38: 0.0337 | AV38: 0.0248 | AW38: Data\CavitySensors\Sensordata_single_export | AX38: 250910 | AY38: 18 | AZ38: Data\ddm\ddm_y_FliesslaengerformBuehler_MachineCycleNo_pw.xml.gz | BA38: Data\dwa\dwa_y_FliesslaengerformBuehler_MachineCycleNo_pw.txt | BB38: Data\ddd\ddd_y_TIMESTAMP_FROM_DWA.xml.gz | BC38: False
A39: or2509-012 | B39: 114 | C39: 114 | D39: 45910 | E39: no optimization | F39: 280 | G39: 0.1 | H39: 420 | I39: 0.1 | K39: 2.5 | L39: 566.1831 | M39: 0.3 | N39: 666.1831 | O39: 679 | P39: 1.25 | Q39: 400 | R39: 400 | S39: 0.07 | T39: 400 | U39: 0.09 | V39: 16 | W39: 10 | X39: 130 | Y39: 180 | Z39: 680 | AA39: 150 | AB39: 130 | AC39: 90 | AD39: 90 | AE39: 160 | AF39: 160 | AG39: 120 | AH39: 60 | AI39: 0.0453 | AJ39: Parametric study | AK39: Air | AL39: F | AM39: 230 AlSi12(Fe) | AN39: 11.31 | AO39: 0.762 | AP39: 0.0351 | AQ39: 0.33 | AR39: 0.024 | AS39: 0.022 | AT39: 0.0131 | AU39: 0.0337 | AV39: 0.0248 | AW39: Data\CavitySensors\Sensordata_single_export | AX39: 250910 | AY39: 19 | AZ39: Data\ddm\ddm_y_FliesslaengerformBuehler_MachineCycleNo_pw.xml.gz | BA39: Data\dwa\dwa_y_FliesslaengerformBuehler_MachineCycleNo_pw.txt | BB39: Data\ddd\ddd_y_TIMESTAMP_FROM_DWA.xml.gz | BC39: False
A40: or2509-013 | B40: 138 | C40: 138 | D40: 45910 | E40: Buehler any | J40: 0.444 | K40: 2 | L40: 486.1831 | M40: 1.6 | N40: 566.1831 | O40: 679 | P40: 1.25 | Q40: 300 | R40: 500 | S40: 0.08 | T40: 600 | U40: 0.16 | V40: 16 | W40: 20 | X40: 130 | Y40: 180 | Z40: 680 | AA40: 150 | AB40: 130 | AC40: 90 | AD40: 90 | AE40: 160 | AF40: 160 | AG40: 120 | AH40: 60 | AI40: 0.0453 | AJ40: Parametric study | AK40: Air | AL40: F | AM40: 230 AlSi12(Fe) | AN40: 11.31 | AO40: 0.762 | AP40: 0.0351 | AQ40: 0.33 | AR40: 0.024 | AS40: 0.022 | AT40: 0.0131 | AU40: 0.0337 | AV40: 0.0248 | AW40: Data\CavitySensors\Sensordata_single_export | AX40: 250910 | AY40: 43 | AZ40: Data\ddm\ddm_y_FliesslaengerformBuehler_MachineCycleNo_pw.xml.gz | BA40: Data\dwa\dwa_y_FliesslaengerformBuehler_MachineCycleNo_pw.txt | BB40: Data\ddd\ddd_y_TIMESTAMP_FROM_DWA.xml.gz | BC40: False
...

Sheet CSV EXPORT CLEANUP
A1: ='or2509 Parameter Sets'!A1 -> Parameter Set | B1: ='or2509 Parameter Sets'!B1 -> Machine Cycle No | C1: ='or2509 Parameter Sets'!C1 -> Casting Part Label | D1: ='or2509 Parameter Sets'!D1 -> Datum | E1: ='or2509 Parameter Sets'!E1 -> type_1st_phase | F1: ='or2509 Parameter Sets'!F1 -> s1 | G1: ='or2509 Parameter Sets'!G1 -> v1 | H1: ='or2509 Parameter Sets'!H1 -> s2 | ... AJ1: ='or2509 Parameter Sets'!AJ1 -> Comment | AK1: ='or2509 Parameter Sets'!AN1 -> Alloy Si | AL1: ='or2509 Parameter Sets'!AO1 -> Alloy Fe | AM1: ='or2509 Parameter Sets'!AP1 -> Alloy Cu | AN1: ='or2509 Parameter Sets'!AQ1 -> Alloy Mn | AO1: ='or2509 Parameter Sets'!AR1 -> Alloy Mg | AP1: ='or2509 Parameter Sets'!AS1 -> Alloy Cr | AQ1: ='or2509 Parameter Sets'!AT1 -> Alloy Ni | AR1: ='or2509 Parameter Sets'!AU1 -> Alloy Zn | ... AZ1: ='or2509 Parameter Sets'!BC1 -> Values corrected from DDM
A2: ='or2509 Parameter Sets'!A2 -> or2509-001 | B2: ='or2509 Parameter Sets'!B2 -> 12 | C2: ='or2509 Parameter Sets'!C2 -> 12 | D2: ='or2509 Parameter Sets'!D2 -> 45908 | E2: ='or2509 Parameter Sets'!E2 -> no optimization | F2: ='or2509 Parameter Sets'!F2 -> 160 | G2: ='or2509 Parameter Sets'!G2 -> 0.2 | H2: ='or2509 Parameter Sets'!H2 -> 399 | ... AJ2: ='or2509 Parameter Sets'!AJ2 -> Parametric study, Baseline repeat | AK2: ='or2509 Parameter Sets'!AN2 -> 11.29 | AL2: ='or2509 Parameter Sets'!AO2 -> 0.737 | AM2: ='or2509 Parameter Sets'!AP2 -> 0.0414 | AN2: ='or2509 Parameter Sets'!AQ2 -> 0.324 | AO2: ='or2509 Parameter Sets'!AR2 -> 0.0273 | AP2: ='or2509 Parameter Sets'!AS2 -> 0.0194 | AQ2: ='or2509 Parameter Sets'!AT2 -> 0.0141 | AR2: ='or2509 Parameter Sets'!AU2 -> 0.0326 | ... AZ2: ='or2509 Parameter Sets'!BC2 -> False
A3: ='or2509 Parameter Sets'!A3 -> or2509-001 | B3: ='or2509 Parameter Sets'!B3 -> 13 | C3: ='or2509 Parameter Sets'!C3 -> 13 | D3: ='or2509 Parameter Sets'!D3 -> 45908 | E3: ='or2509 Parameter Sets'!E3 -> no optimization | F3: ='or2509 Parameter Sets'!F3 -> 160 | G3: ='or2509 Parameter Sets'!G3 -> 0.2 | H3: ='or2509 Parameter Sets'!H3 -> 399 | ... AJ3: ='or2509 Parameter Sets'!AJ3 -> Parametric study, Baseline repeat | AK3: ='or2509 Parameter Sets'!AN3 -> 11.29 | AL3: ='or2509 Parameter Sets'!AO3 -> 0.737 | AM3: ='or2509 Parameter Sets'!AP3 -> 0.0414 | AN3: ='or2509 Parameter Sets'!AQ3 -> 0.324 | AO3: ='or2509 Parameter Sets'!AR3 -> 0.0273 | AP3: ='or2509 Parameter Sets'!AS3 -> 0.0194 | AQ3: ='or2509 Parameter Sets'!AT3 -> 0.0141 | AR3: ='or2509 Parameter Sets'!AU3 -> 0.0326 | ... AZ3: ='or2509 Parameter Sets'!BC3 -> False
A4: ='or2509 Parameter Sets'!A4 -> or2509-001 | B4: ='or2509 Parameter Sets'!B4 -> 14 | C4: ='or2509 Parameter Sets'!C4 -> 14 | D4: ='or2509 Parameter Sets'!D4 -> 45908 | E4: ='or2509 Parameter Sets'!E4 -> no optimization | F4: ='or2509 Parameter Sets'!F4 -> 160 | G4: ='or2509 Parameter Sets'!G4 -> 0.2 | H4: ='or2509 Parameter Sets'!H4 -> 399 | ... AJ4: ='or2509 Parameter Sets'!AJ4 -> Parametric study, Baseline repeat | AK4: ='or2509 Parameter Sets'!AN4 -> 11.29 | AL4: ='or2509 Parameter Sets'!AO4 -> 0.737 | AM4: ='or2509 Parameter Sets'!AP4 -> 0.0414 | AN4: ='or2509 Parameter Sets'!AQ4 -> 0.324 | AO4: ='or2509 Parameter Sets'!AR4 -> 0.0273 | AP4: ='or2509 Parameter Sets'!AS4 -> 0.0194 | AQ4: ='or2509 Parameter Sets'!AT4 -> 0.0141 | AR4: ='or2509 Parameter Sets'!AU4 -> 0.0326 | ... AZ4: ='or2509 Parameter Sets'!BC4 -> False
A5: ='or2509 Parameter Sets'!A6 -> or2509-002 | B5: ='or2509 Parameter Sets'!B6 -> 30 | C5: ='or2509 Parameter Sets'!C6 -> 30 | D5: ='or2509 Parameter Sets'!D6 -> 45909 | E5: ='or2509 Parameter Sets'!E6 -> Buehler any | F5: ='or2509 Parameter Sets'!F6 -> 0 | G5: ='or2509 Parameter Sets'!G6 -> 0 | H5: ='or2509 Parameter Sets'!H6 -> 0 | ... AJ5: ='or2509 Parameter Sets'!AJ6 -> Parametric study | AK5: ='or2509 Parameter Sets'!AN6 -> 11.35 | AL5: ='or2509 Parameter Sets'!AO6 -> 0.765 | AM5: ='or2509 Parameter Sets'!AP6 -> 0.0357 | AN5: ='or2509 Parameter Sets'!AQ6 -> 0.331 | AO5: ='or2509 Parameter Sets'!AR6 -> 0.0251 | AP5: ='or2509 Parameter Sets'!AS6 -> 0.0218 | AQ5: ='or2509 Parameter Sets'!AT6 -> 0.0132 | AR5: ='or2509 Parameter Sets'!AU6 -> 0.034 | ... AZ5: ='or2509 Parameter Sets'!BC6 -> False
A6: ='or2509 Parameter Sets'!A7 -> or2509-002 | B6: ='or2509 Parameter Sets'!B7 -> 31 | C6: ='or2509 Parameter Sets'!C7 -> 31 | D6: ='or2509 Parameter Sets'!D7 -> 45909 | E6: ='or2509 Parameter Sets'!E7 -> Buehler any | F6: ='or2509 Parameter Sets'!F7 -> 0 | G6: ='or2509 Parameter Sets'!G7 -> 0 | H6: ='or2509 Parameter Sets'!H7 -> 0 | ... AJ6: ='or2509 Parameter Sets'!AJ7 -> Parametric study | AK6: ='or2509 Parameter Sets'!AN7 -> 11.35 | AL6: ='or2509 Parameter Sets'!AO7 -> 0.765 | AM6: ='or2509 Parameter Sets'!AP7 -> 0.0357 | AN6: ='or2509 Parameter Sets'!AQ7 -> 0.331 | AO6: ='or2509 Parameter Sets'!AR7 -> 0.0251 | AP6: ='or2509 Parameter Sets'!AS7 -> 0.0218 | AQ6: ='or2509 Parameter Sets'!AT7 -> 0.0132 | AR6: ='or2509 Parameter Sets'!AU7 -> 0.034 | ... AZ6: ='or2509 Parameter Sets'!BC7 -> False
A7: ='or2509 Parameter Sets'!A8 -> or2509-002 | B7: ='or2509 Parameter Sets'!B8 -> 32 | C7: ='or2509 Parameter Sets'!C8 -> 32 | D7: ='or2509 Parameter Sets'!D8 -> 45909 | E7: ='or2509 Parameter Sets'!E8 -> Buehler any | F7: ='or2509 Parameter Sets'!F8 -> 0 | G7: ='or2509 Parameter Sets'!G8 -> 0 | H7: ='or2509 Parameter Sets'!H8 -> 0 | ... AJ7: ='or2509 Parameter Sets'!AJ8 -> Parametric study | AK7: ='or2509 Parameter Sets'!AN8 -> 11.35 | AL7: ='or2509 Parameter Sets'!AO8 -> 0.765 | AM7: ='or2509 Parameter Sets'!AP8 -> 0.0357 | AN7: ='or2509 Parameter Sets'!AQ8 -> 0.331 | AO7: ='or2509 Parameter Sets'!AR8 -> 0.0251 | AP7: ='or2509 Parameter Sets'!AS8 -> 0.0218 | AQ7: ='or2509 Parameter Sets'!AT8 -> 0.0132 | AR7: ='or2509 Parameter Sets'!AU8 -> 0.034 | ... AZ7: ='or2509 Parameter Sets'!BC8 -> False
A8: ='or2509 Parameter Sets'!A9 -> or2509-003 | B8: ='or2509 Parameter Sets'!B9 -> 37 | C8: ='or2509 Parameter Sets'!C9 -> 37 | D8: ='or2509 Parameter Sets'!D9 -> 45909 | E8: ='or2509 Parameter Sets'!E9 -> Buehler any | F8: ='or2509 Parameter Sets'!F9 -> 0 | G8: ='or2509 Parameter Sets'!G9 -> 0 | H8: ='or2509 Parameter Sets'!H9 -> 0 | ... AJ8: ='or2509 Parameter Sets'!AJ9 -> Parametric study | AK8: ='or2509 Parameter Sets'!AN9 -> 11.35 | AL8: ='or2509 Parameter Sets'!AO9 -> 0.765 | AM8: ='or2509 Parameter Sets'!AP9 -> 0.0357 | AN8: ='or2509 Parameter Sets'!AQ9 -> 0.331 | AO8: ='or2509 Parameter Sets'!AR9 -> 0.0251 | AP8: ='or2509 Parameter Sets'!AS9 -> 0.0218 | AQ8: ='or2509 Parameter Sets'!AT9 -> 0.0132 | AR8: ='or2509 Parameter Sets'!AU9 -> 0.034 | ... AZ8: ='or2509 Parameter Sets'!BC9 -> True
A9: ='or2509 Parameter Sets'!A10 -> or2509-003 | B9: ='or2509 Parameter Sets'!B10 -> 38 | C9: ='or2509 Parameter Sets'!C10 -> lost | D9: ='or2509 Parameter Sets'!D10 -> 45909 | E9: ='or2509 Parameter Sets'!E10 -> Buehler any | F9: ='or2509 Parameter Sets'!F10 -> 0 | G9: ='or2509 Parameter Sets'!G10 -> 0 | H9: ='or2509 Parameter Sets'!H10 -> 0 | ... AJ9: ='or2509 Parameter Sets'!AJ10 -> Parametric study | AK9: ='or2509 Parameter Sets'!AN10 -> 11.35 | AL9: ='or2509 Parameter Sets'!AO10 -> 0.765 | AM9: ='or2509 Parameter Sets'!AP10 -> 0.0357 | AN9: ='or2509 Parameter Sets'!AQ10 -> 0.331 | AO9: ='or2509 Parameter Sets'!AR10 -> 0.0251 | AP9: ='or2509 Parameter Sets'!AS10 -> 0.0218 | AQ9: ='or2509 Parameter Sets'!AT10 -> 0.0132 | AR9: ='or2509 Parameter Sets'!AU10 -> 0.034 | ... AZ9: ='or2509 Parameter Sets'!BC10 -> True
A10: ='or2509 Parameter Sets'!A11 -> or2509-003 | B10: ='or2509 Parameter Sets'!B11 -> 39 | C10: ='or2509 Parameter Sets'!C11 -> 39 | D10: ='or2509 Parameter Sets'!D11 -> 45909 | E10: ='or2509 Parameter Sets'!E11 -> Buehler any | F10: ='or2509 Parameter Sets'!F11 -> 0 | G10: ='or2509 Parameter Sets'!G11 -> 0 | H10: ='or2509 Parameter Sets'!H11 -> 0 | ... AJ10: ='or2509 Parameter Sets'!AJ11 -> Parametric study | AK10: ='or2509 Parameter Sets'!AN11 -> 11.35 | AL10: ='or2509 Parameter Sets'!AO11 -> 0.765 | AM10: ='or2509 Parameter Sets'!AP11 -> 0.0357 | AN10: ='or2509 Parameter Sets'!AQ11 -> 0.331 | AO10: ='or2509 Parameter Sets'!AR11 -> 0.0251 | AP10: ='or2509 Parameter Sets'!AS11 -> 0.0218 | AQ10: ='or2509 Parameter Sets'!AT11 -> 0.0132 | AR10: ='or2509 Parameter Sets'!AU11 -> 0.034 | ... AZ10: ='or2509 Parameter Sets'!BC11 -> True
A11: ='or2509 Parameter Sets'!A12 -> or2509-004 | B11: ='or2509 Parameter Sets'!B12 -> 48 | C11: ='or2509 Parameter Sets'!C12 -> 48 | D11: ='or2509 Parameter Sets'!D12 -> 45909 | E11: ='or2509 Parameter Sets'!E12 -> Nogowizin | F11: ='or2509 Parameter Sets'!F12 -> 0 | G11: ='or2509 Parameter Sets'!G12 -> 0 | H11: ='or2509 Parameter Sets'!H12 -> 0 | ... AJ11: ='or2509 Parameter Sets'!AJ12 -> Parametric study | AK11: ='or2509 Parameter Sets'!AN12 -> 11.35 | AL11: ='or2509 Parameter Sets'!AO12 -> 0.765 | AM11: ='or2509 Parameter Sets'!AP12 -> 0.0357 | AN11: ='or2509 Parameter Sets'!AQ12 -> 0.331 | AO11: ='or2509 Parameter Sets'!AR12 -> 0.0251 | AP11: ='or2509 Parameter Sets'!AS12 -> 0.0218 | AQ11: ='or2509 Parameter Sets'!AT12 -> 0.0132 | AR11: ='or2509 Parameter Sets'!AU12 -> 0.034 | ... AZ11: ='or2509 Parameter Sets'!BC12 -> False
A12: ='or2509 Parameter Sets'!A13 -> or2509-004 | B12: ='or2509 Parameter Sets'!B13 -> 49 | C12: ='or2509 Parameter Sets'!C13 -> 49 | D12: ='or2509 Parameter Sets'!D13 -> 45909 | E12: ='or2509 Parameter Sets'!E13 -> Nogowizin | F12: ='or2509 Parameter Sets'!F13 -> 0 | G12: ='or2509 Parameter Sets'!G13 -> 0 | H12: ='or2509 Parameter Sets'!H13 -> 0 | ... AJ12: ='or2509 Parameter Sets'!AJ13 -> Parametric study | AK12: ='or2509 Parameter Sets'!AN13 -> 11.35 | AL12: ='or2509 Parameter Sets'!AO13 -> 0.765 | AM12: ='or2509 Parameter Sets'!AP13 -> 0.0357 | AN12: ='or2509 Parameter Sets'!AQ13 -> 0.331 | AO12: ='or2509 Parameter Sets'!AR13 -> 0.0251 | AP12: ='or2509 Parameter Sets'!AS13 -> 0.0218 | AQ12: ='or2509 Parameter Sets'!AT13 -> 0.0132 | AR12: ='or2509 Parameter Sets'!AU13 -> 0.034 | ... AZ12: ='or2509 Parameter Sets'!BC13 -> False
A13: ='or2509 Parameter Sets'!A14 -> or2509-004 | B13: ='or2509 Parameter Sets'!B14 -> 50 | C13: ='or2509 Parameter Sets'!C14 -> 50 | D13: ='or2509 Parameter Sets'!D14 -> 45909 | E13: ='or2509 Parameter Sets'!E14 -> Nogowizin | F13: ='or2509 Parameter Sets'!F14 -> 0 | G13: ='or2509 Parameter Sets'!G14 -> 0 | H13: ='or2509 Parameter Sets'!H14 -> 0 | ... AJ13: ='or2509 Parameter Sets'!AJ14 -> Parametric study | AK13: ='or2509 Parameter Sets'!AN14 -> 11.35 | AL13: ='or2509 Parameter Sets'!AO14 -> 0.765 | AM13: ='or2509 Parameter Sets'!AP14 -> 0.0357 | AN13: ='or2509 Parameter Sets'!AQ14 -> 0.331 | AO13: ='or2509 Parameter Sets'!AR14 -> 0.0251 | AP13: ='or2509 Parameter Sets'!AS14 -> 0.0218 | AQ13: ='or2509 Parameter Sets'!AT14 -> 0.0132 | AR13: ='or2509 Parameter Sets'!AU14 -> 0.034 | ... AZ13: ='or2509 Parameter Sets'!BC14 -> False
A14: ='or2509 Parameter Sets'!A15 -> or2509-005 | B14: ='or2509 Parameter Sets'!B15 -> 57 | C14: ='or2509 Parameter Sets'!C15 -> 57 | D14: ='or2509 Parameter Sets'!D15 -> 45909 | E14: ='or2509 Parameter Sets'!E15 -> Buehler any | F14: ='or2509 Parameter Sets'!F15 -> 0 | G14: ='or2509 Parameter Sets'!G15 -> 0 | H14: ='or2509 Parameter Sets'!H15 -> 0 | ... AJ14: ='or2509 Parameter Sets'!AJ15 -> Parametric study | AK14: ='or2509 Parameter Sets'!AN15 -> 11.35 | AL14: ='or2509 Parameter Sets'!AO15 -> 0.765 | AM14: ='or2509 Parameter Sets'!AP15 -> 0.0357 | AN14: ='or2509 Parameter Sets'!AQ15 -> 0.331 | AO14: ='or2509 Parameter Sets'!AR15 -> 0.0251 | AP14: ='or2509 Parameter Sets'!AS15 -> 0.0218 | AQ14: ='or2509 Parameter Sets'!AT15 -> 0.0132 | AR14: ='or2509 Parameter Sets'!AU15 -> 0.034 | ... AZ14: ='or2509 Parameter Sets'!BC15 -> True
A15: ='or2509 Parameter Sets'!A16 -> or2509-005 | B15: ='or2509 Parameter Sets'!B16 -> 58 | C15: ='or2509 Parameter Sets'!C16 -> 58 | D15: ='or2509 Parameter Sets'!D16 -> 45909 | E15: ='or2509 Parameter Sets'!E16 -> Buehler any | F15: ='or2509 Parameter Sets'!F16 -> 0 | G15: ='or2509 Parameter Sets'!G16 -> 0 | H15: ='or2509 Parameter Sets'!H16 -> 0 | ... AJ15: ='or2509 Parameter Sets'!AJ16 -> Parametric study | AK15: ='or2509 Parameter Sets'!AN16 -> 11.35 | AL15: ='or2509 Parameter Sets'!AO16 -> 0.765 | AM15: ='or2509 Parameter Sets'!AP16 -> 0.0357 | AN15: ='or2509 Parameter Sets'!AQ16 -> 0.331 | AO15: ='or2509 Parameter Sets'!AR16 -> 0.0251 | AP15: ='or2509 Parameter Sets'!AS16 -> 0.0218 | AQ15: ='or2509 Parameter Sets'!AT16 -> 0.0132 | AR15: ='or2509 Parameter Sets'!AU16 -> 0.034 | ... AZ15: ='or2509 Parameter Sets'!BC16 -> True
A16: ='or2509 Parameter Sets'!A17 -> or2509-005 | B16: ='or2509 Parameter Sets'!B17 -> 59 | C16: ='or2509 Parameter Sets'!C17 -> 59 | D16: ='or2509 Parameter Sets'!D17 -> 45909 | E16: ='or2509 Parameter Sets'!E17 -> Buehler any | F16: ='or2509 Parameter Sets'!F17 -> 0 | G16: ='or2509 Parameter Sets'!G17 -> 0 | H16: ='or2509 Parameter Sets'!H17 -> 0 | ... AJ16: ='or2509 Parameter Sets'!AJ17 -> Parametric study | AK16: ='or2509 Parameter Sets'!AN17 -> 11.35 | AL16: ='or2509 Parameter Sets'!AO17 -> 0.765 | AM16: ='or2509 Parameter Sets'!AP17 -> 0.0357 | AN16: ='or2509 Parameter Sets'!AQ17 -> 0.331 | AO16: ='or2509 Parameter Sets'!AR17 -> 0.0251 | AP16: ='or2509 Parameter Sets'!AS17 -> 0.0218 | AQ16: ='or2509 Parameter Sets'!AT17 -> 0.0132 | AR16: ='or2509 Parameter Sets'!AU17 -> 0.034 | ... AZ16: ='or2509 Parameter Sets'!BC17 -> True
... A22: ='or2509 Parameter Sets'!A23 -> or2509-007 | B22: ='or2509 Parameter Sets'!B23 -> 71 | C22: ='or2509 Parameter Sets'!C23 -> 71 | D22: ='or2509 Parameter Sets'!D23 -> 45909 | E22: ='or2509 Parameter Sets'!E23 -> Nogowizin | F22: ='or2509 Parameter Sets'!F23 -> 0 | G22: ='or2509 Parameter Sets'!G23 -> 0 | H22: ='or2509 Parameter Sets'!H23 -> 0 | ... AJ22: ='or2509 Parameter Sets'!AJ23 -> Parametric study | AK22: ='or2509 Parameter Sets'!AN23 -> 11.35 | AL22: ='or2509 Parameter Sets'!AO23 -> 0.765 | AM22: ='or2509 Parameter Sets'!AP23 -> 0.0357 | AN22: ='or2509 Parameter Sets'!AQ23 -> 0.331 | AO22: ='or2509 Parameter Sets'!AR23 -> 0.0251 | AP22: ='or2509 Parameter Sets'!AS23 -> 0.0218 | AQ22: ='or2509 Parameter Sets'!AT23 -> 0.0132 | AR22: ='or2509 Parameter Sets'!AU23 -> 0.034 | ... AZ22: ='or2509 Parameter Sets'!BC23 -> False
A23: ='or2509 Parameter Sets'!A25 -> or2509-008 | B23: ='or2509 Parameter Sets'!B25 -> 79 | C23: ='or2509 Parameter Sets'!C25 -> 79 | D23: ='or2509 Parameter Sets'!D25 -> 45909 | E23: ='or2509 Parameter Sets'!E25 -> Nogowizin | F23: ='or2509 Parameter Sets'!F25 -> 0 | G23: ='or2509 Parameter Sets'!G25 -> 0 | H23: ='or2509 Parameter Sets'!H25 -> 0 | ... AJ23: ='or2509 Parameter Sets'!AJ25 -> Parametric study | AK23: ='or2509 Parameter Sets'!AN25 -> 11.35 | AL23: ='or2509 Parameter Sets'!AO25 -> 0.765 | AM23: ='or2509 Parameter Sets'!AP25 -> 0.0357 | AN23: ='or2509 Parameter Sets'!AQ25 -> 0.331 | AO23: ='or2509 Parameter Sets'!AR25 -> 0.0251 | AP23: ='or2509 Parameter Sets'!AS25 -> 0.0218 | AQ23: ='or2509 Parameter Sets'!AT25 -> 0.0132 | AR23: ='or2509 Parameter Sets'!AU25 -> 0.034 | ... AZ23: ='or2509 Parameter Sets'!BC25 -> True
A24: ='or2509 Parameter Sets'!A26 -> or2509-008 | B24: ='or2509 Parameter Sets'!B26 -> 80 | C24: ='or2509 Parameter Sets'!C26 -> 80 | D24: ='or2509 Parameter Sets'!D26 -> 45909 | E24: ='or2509 Parameter Sets'!E26 -> Nogowizin | F24: ='or2509 Parameter Sets'!F26 -> 0 | G24: ='or2509 Parameter Sets'!G26 -> 0 | H24: ='or2509 Parameter Sets'!H26 -> 0 | ... AJ24: ='or2509 Parameter Sets'!AJ26 -> Parametric study | AK24: ='or2509 Parameter Sets'!AN26 -> 11.35 | AL24: ='or2509 Parameter Sets'!AO26 -> 0.765 | AM24: ='or2509 Parameter Sets'!AP26 -> 0.0357 | AN24: ='or2509 Parameter Sets'!AQ26 -> 0.331 | AO24: ='or2509 Parameter Sets'!AR26 -> 0.0251 | AP24: ='or2509 Parameter Sets'!AS26 -> 0.0218 | AQ24: ='or2509 Parameter Sets'!AT26 -> 0.0132 | AR24: ='or2509 Parameter Sets'!AU26 -> 0.034 | ... AZ24: ='or2509 Parameter Sets'!BC26 -> True
A25: ='or2509 Parameter Sets'!A27 -> or2509-008 | B25: ='or2509 Parameter Sets'!B27 -> 81 | C25: ='or2509 Parameter Sets'!C27 -> 81 | D25: ='or2509 Parameter Sets'!D27 -> 45909 | E25: ='or2509 Parameter Sets'!E27 -> Nogowizin | F25: ='or2509 Parameter Sets'!F27 -> 0 | G25: ='or2509 Parameter Sets'!G27 -> 0 | H25: ='or2509 Parameter Sets'!H27 -> 0 | ... AJ25: ='or2509 Parameter Sets'!AJ27 -> Parametric study | AK25: ='or2509 Parameter Sets'!AN27 -> 11.35 | AL25: ='or2509 Parameter Sets'!AO27 -> 0.765 | AM25: ='or2509 Parameter Sets'!AP27 -> 0.0357 | AN25: ='or2509 Parameter Sets'!AQ27 -> 0.331 | AO25: ='or2509 Parameter Sets'!AR27 -> 0.0251 | AP25: ='or2509 Parameter Sets'!AS27 -> 0.0218 | AQ25: ='or2509 Parameter Sets'!AT27 -> 0.0132 | AR25: ='or2509 Parameter Sets'!AU27 -> 0.034 | ... AZ25: ='or2509 Parameter Sets'!BC27 -> True
A26: ='or2509 Parameter Sets'!A28 -> or2509-009 | B26: ='or2509 Parameter Sets'!B28 -> 85 | C26: ='or2509 Parameter Sets'!C28 -> 85 | D26: ='or2509 Parameter Sets'!D28 -> 45909 | E26: ='or2509 Parameter Sets'!E28 -> Buehler any | F26: ='or2509 Parameter Sets'!F28 -> 0 | G26: ='or2509 Parameter Sets'!G28 -> 0 | H26: ='or2509 Parameter Sets'!H28 -> 0 | ... AJ26: ='or2509 Parameter Sets'!AJ28 -> Parametric study | AK26: ='or2509 Parameter Sets'!AN28 -> 11.35 | AL26: ='or2509 Parameter Sets'!AO28 -> 0.765 | AM26: ='or2509 Parameter Sets'!AP28 -> 0.0357 | AN26: ='or2509 Parameter Sets'!AQ28 -> 0.331 | AO26: ='or2509 Parameter Sets'!AR28 -> 0.0251 | AP26: ='or2509 Parameter Sets'!AS28 -> 0.0218 | AQ26: ='or2509 Parameter Sets'!AT28 -> 0.0132 | AR26: ='or2509 Parameter Sets'!AU28 -> 0.034 | ... AZ26: ='or2509 Parameter Sets'!BC28 -> False
A27: ='or2509 Parameter Sets'!A29 -> or2509-009 | B27: ='or2509 Parameter Sets'!B29 -> 86 | C27: ='or2509 Parameter Sets'!C29 -> 86 | D27: ='or2509 Parameter Sets'!D29 -> 45909 | E27: ='or2509 Parameter Sets'!E29 -> Buehler any | F27: ='or2509 Parameter Sets'!F29 -> 0 | G27: ='or2509 Parameter Sets'!G29 -> 0 | H27: ='or2509 Parameter Sets'!H29 -> 0 | ... AJ27: ='or2509 Parameter Sets'!AJ29 -> Parametric study | AK27: ='or2509 Parameter Sets'!AN29 -> 11.35 | AL27: ='or2509 Parameter Sets'!AO29 -> 0.765 | AM27: ='or2509 Parameter Sets'!AP29 -> 0.0357 | AN27: ='or2509 Parameter Sets'!AQ29 -> 0.331 | AO27: ='or2509 Parameter Sets'!AR29 -> 0.0251 | AP27: ='or2509 Parameter Sets'!AS29 -> 0.0218 | AQ27: ='or2509 Parameter Sets'!AT29 -> 0.0132 | AR27: ='or2509 Parameter Sets'!AU29 -> 0.034 | ... AZ27: ='or2509 Parameter Sets'!BC29 -> False
A28: ='or2509 Parameter Sets'!A30 -> or2509-009 | B28: ='or2509 Parameter Sets'!B30 -> 87 | C28: ='or2509 Parameter Sets'!C30 -> 87 | D28: ='or2509 Parameter Sets'!D30 -> 45909 | E28: ='or2509 Parameter Sets'!E30 -> Buehler any | F28: ='or2509 Parameter Sets'!F30 -> 0 | G28: ='or2509 Parameter Sets'!G30 -> 0 | H28: ='or2509 Parameter Sets'!H30 -> 0 | ... AJ28: ='or2509 Parameter Sets'!AJ30 -> Parametric study | AK28: ='or2509 Parameter Sets'!AN30 -> 11.35 | AL28: ='or2509 Parameter Sets'!AO30 -> 0.765 | AM28: ='or2509 Parameter Sets'!AP30 -> 0.0357 | AN28: ='or2509 Parameter Sets'!AQ30 -> 0.331 | AO28: ='or2509 Parameter Sets'!AR30 -> 0.0251 | AP28: ='or2509 Parameter Sets'!AS30 -> 0.0218 | AQ28: ='or2509 Parameter Sets'!AT30 -> 0.0132 | AR28: ='or2509 Parameter Sets'!AU30 -> 0.034 | ... AZ28: ='or2509 Parameter Sets'!BC30 -> False
A29: ='or2509 Parameter Sets'!A31 -> or2509-010 | B29: ='or2509 Parameter Sets'!B31 -> 91 | C29: ='or2509 Parameter Sets'!C31 -> 91 | D29: ='or2509 Parameter Sets'!D31 -> 45909 | E29: ='or2509 Parameter Sets'!E31 -> Buehler any | F29: ='or2509 Parameter Sets'!F31 -> 0 | G29: ='or2509 Parameter Sets'!G31 -> 0 | H29: ='or2509 Parameter Sets'!H31 -> 0 | ... AJ29: ='or2509 Parameter Sets'!AJ31 -> Parametric study | AK29: ='or2509 Parameter Sets'!AN31 -> 11.35 | AL29: ='or2509 Parameter Sets'!AO31 -> 0.765 | AM29: ='or2509 Parameter Sets'!AP31 -> 0.0357 | AN29: ='or2509 Parameter Sets'!AQ31 -> 0.331 | AO29: ='or2509 Parameter Sets'!AR31 -> 0.0251 | AP29: ='or2509 Parameter Sets'!AS31 -> 0.0218 | AQ29: ='or2509 Parameter Sets'!AT31 -> 0.0132 | AR29: ='or2509 Parameter Sets'!AU31 -> 0.034 | ... AZ29: ='or2509 Parameter Sets'!BC31 -> False
A30: ='or2509 Parameter Sets'!A32 -> or2509-010 | B30: ='or2509 Parameter Sets'!B32 -> 92 | C30: ='or2509 Parameter Sets'!C32 -> 92 | D30: ='or2509 Parameter Sets'!D32 -> 45909 | E30: ='or2509 Parameter Sets'!E32 -> Buehler any | F30: ='or2509 Parameter Sets'!F32 -> 0 | G30: ='or2509 Parameter Sets'!G32 -> 0 | H30: ='or2509 Parameter Sets'!H32 -> 0 | ... AJ30: ='or2509 Parameter Sets'!AJ32 -> Parametric study | AK30: ='or2509 Parameter Sets'!AN32 -> 11.35 | AL30: ='or2509 Parameter Sets'!AO32 -> 0.765 | AM30: ='or2509 Parameter Sets'!AP32 -> 0.0357 | AN30: ='or2509 Parameter Sets'!AQ32 -> 0.331 | AO30: ='or2509 Parameter Sets'!AR32 -> 0.0251 | AP30: ='or2509 Parameter Sets'!AS32 -> 0.0218 | AQ30: ='or2509 Parameter Sets'!AT32 -> 0.0132 | AR30: ='or2509 Parameter Sets'!AU32 -> 0.034 | ... AZ30: ='or2509 Parameter Sets'!BC32 -> False
A31: ='or2509 Parameter Sets'!A33 -> or2509-010 | B31: ='or2509 Parameter Sets'!B33 -> 93 | C31: ='or2509 Parameter Sets'!C33 -> 93 | D31: ='or2509 Parameter Sets'!D33 -> 45909 | E31: ='or2509 Parameter Sets'!E33 -> Buehler any | F31: ='or2509 Parameter Sets'!F33 -> 0 | G31: ='or2509 Parameter Sets'!G33 -> 0 | H31: ='or2509 Parameter Sets'!H33 -> 0 | ... AJ31: ='or2509 Parameter Sets'!AJ33 -> Parametric study | AK31: ='or2509 Parameter Sets'!AN33 -> 11.35 | AL31: ='or2509 Parameter Sets'!AO33 -> 0.765 | AM31: ='or2509 Parameter Sets'!AP33 -> 0.0357 | AN31: ='or2509 Parameter Sets'!AQ33 -> 0.331 | AO31: ='or2509 Parameter Sets'!AR33 -> 0.0251 | AP31: ='or2509 Parameter Sets'!AS33 -> 0.0218 | AQ31: ='or2509 Parameter Sets'!AT33 -> 0.0132 | AR31: ='or2509 Parameter Sets'!AU33 -> 0.034 | ... AZ31: ='or2509 Parameter Sets'!BC33 -> False
A32: ='or2509 Parameter Sets'!A34 -> or2509-011 | B32: ='or2509 Parameter Sets'!B34 -> 104 | C32: ='or2509 Parameter Sets'!C34 -> 104 | D32: ='or2509 Parameter Sets'!D34 -> 45910 | E32: ='or2509 Parameter Sets'!E34 -> Nogowizin | F32: ='or2509 Parameter Sets'!F34 -> 0 | G32: ='or2509 Parameter Sets'!G34 -> 0 | H32: ='or2509 Parameter Sets'!H34 -> 0 | ... AJ32: ='or2509 Parameter Sets'!AJ34 -> Parametric study | AK32: ='or2509 Parameter Sets'!AN34 -> 11.31 | AL32: ='or2509 Parameter Sets'!AO34 -> 0.762 | AM32: ='or2509 Parameter Sets'!AP34 -> 0.0351 | AN32: ='or2509 Parameter Sets'!AQ34 -> 0.33 | AO32: ='or2509 Parameter Sets'!AR34 -> 0.024 | AP32: ='or2509 Parameter Sets'!AS34 -> 0.022 | AQ32: ='or2509 Parameter Sets'!AT34 -> 0.0131 | AR32: ='or2509 Parameter Sets'!AU34 -> 0.0337 | ... AZ32: ='or2509 Parameter Sets'!BC34 -> False
A33: ='or2509 Parameter Sets'!A35 -> or2509-011 | B33: ='or2509 Parameter Sets'!B35 -> 105 | C33: ='or2509 Parameter Sets'!C35 -> 105 | D33: ='or2509 Parameter Sets'!D35 -> 45910 | E33: ='or2509 Parameter Sets'!E35 -> Nogowizin | F33: ='or2509 Parameter Sets'!F35 -> 0 | G33: ='or2509 Parameter Sets'!G35 -> 0 | H33: ='or2509 Parameter Sets'!H35 -> 0 | ... AJ33: ='or2509 Parameter Sets'!AJ35 -> Parametric study | AK33: ='or2509 Parameter Sets'!AN35 -> 11.31 | AL33: ='or2509 Parameter Sets'!AO35 -> 0.762 | AM33: ='or2509 Parameter Sets'!AP35 -> 0.0351 | AN33: ='or2509 Parameter Sets'!AQ35 -> 0.33 | AO33: ='or2509 Parameter Sets'!AR35 -> 0.024 | AP33: ='or2509 Parameter Sets'!AS35 -> 0.022 | AQ33: ='or2509 Parameter Sets'!AT35 -> 0.0131 | AR33: ='or2509 Parameter Sets'!AU35 -> 0.0337 | ... AZ33: ='or2509 Parameter Sets'!BC35 -> False
A34: ='or2509 Parameter Sets'!A36 -> or2509-011 | B34: ='or2509 Parameter Sets'!B36 -> 106 | C34: ='or2509 Parameter Sets'!C36 -> 106 | D34: ='or2509 Parameter Sets'!D36 -> 45910 | E34: ='or2509 Parameter Sets'!E36 -> Nogowizin | F34: ='or2509 Parameter Sets'!F36 -> 0 | G34: ='or2509 Parameter Sets'!G36 -> 0 | H34: ='or2509 Parameter Sets'!H36 -> 0 | ... AJ34: ='or2509 Parameter Sets'!AJ36 -> Parametric study | AK34: ='or2509 Parameter Sets'!AN36 -> 11.31 | AL34: ='or2509 Parameter Sets'!AO36 -> 0.762 | AM34: ='or2509 Parameter Sets'!AP36 -> 0.0351 | AN34: ='or2509 Parameter Sets'!AQ36 -> 0.33 | AO34: ='or2509 Parameter Sets'!AR36 -> 0.024 | AP34: ='or2509 Parameter Sets'!AS36 -> 0.022 | AQ34: ='or2509 Parameter Sets'!AT36 -> 0.0131 | AR34: ='or2509 Parameter Sets'!AU36 -> 0.0337 | ... AZ34: ='or2509 Parameter Sets'!BC36 -> False
... A127: ='or2509 Parameter Sets'!A129 -> or2509-042 | B127: ='or2509 Parameter Sets'!B129 -> 328 | C127: ='or2509 Parameter Sets'!C129 -> 328 | D127: ='or2509 Parameter Sets'!D129 -> 45912 | E127: ='or2509 Parameter Sets'!E129 -> no optimization | F127: ='or2509 Parameter Sets'!F129 -> 160 | G127: ='or2509 Parameter Sets'!G129 -> 0.5 | H127: ='or2509 Parameter Sets'!H129 -> 380 | ... AJ127: ='or2509 Parameter Sets'!AJ129 -> Parametric study | AK127: ='or2509 Parameter Sets'!AN129 -> 11.37 | AL127: ='or2509 Parameter Sets'!AO129 -> 0.773 | AM127: ='or2509 Parameter Sets'!AP129 -> 0.036 | AN127: ='or2509 Parameter Sets'!AQ129 -> 0.327 | AO127: ='or2509 Parameter Sets'!AR129 -> 0.0222 | AP127: ='or2509 Parameter Sets'!AS129 -> 0.0222 | AQ127: ='or2509 Parameter Sets'!AT129 -> 0.0135 | AR127: ='or2509 Parameter Sets'!AU129 -> 0.0342 | ... AZ127: ='or2509 Parameter Sets'!BC129 -> False
A128: ='or2509 Parameter Sets'!A135 -> or2509-000 | B128: ='or2509 Parameter Sets'!B135 -> 414394 | C128: ='or2509 Parameter Sets'!C135 -> 394 | D128: ='or2509 Parameter Sets'!D135 -> 45905 | E128: ='or2509 Parameter Sets'!E135 -> no optimization | F128: ='or2509 Parameter Sets'!F135 -> 160 | G128: ='or2509 Parameter Sets'!G135 -> 0.2 | H128: ='or2509 Parameter Sets'!H135 -> 399 | ... AJ128: ='or2509 Parameter Sets'!AJ135 -> Baseline, thermal balance study | AK128: ='or2509 Parameter Sets'!AN135 -> 11.21 | AL128: ='or2509 Parameter Sets'!AO135 -> 0.651 | AM128: ='or2509 Parameter Sets'!AP135 -> 0.04 | AN128: ='or2509 Parameter Sets'!AQ135 -> 0.261 | AO128: ='or2509 Parameter Sets'!AR135 -> 0.0324 | AP128: ='or2509 Parameter Sets'!AS135 -> 0.0137 | AQ128: ='or2509 Parameter Sets'!AT135 -> 0.014 | AR128: ='or2509 Parameter Sets'!AU135 -> 0.0314 | ... AZ128: ='or2509 Parameter Sets'!BC135 -> False
